Workbook

Sheet KPI
A1: indicadores de performance - kpi's - 2026
A4: GESTÃO FÁBRICA | B4: OEE - TECNOLOGIA - % | C4: 0.9 | O4: MÉDIAS | Q4: total produzido/total planejadoX100
B5: Períodos | C5: Janeiro | D5: Fevereiro | E5: Março | F5: Abril | G5: Maio | H5: Junho | I5: Julho | J5: Agosto | K5: Setembro | L5: Outubro | M5: Novembro | N5: Dezembro
B6: Resultados | C6: =GESTÃO!D91 -> 83.19 | D6: =GESTÃO!E91 -> 81.54 | E6: =GESTÃO!F91 -> 82.13 | F6: =GESTÃO!G91 -> 83.45 | G6: =GESTÃO!H91 -> 81.61 | H6: =GESTÃO!I91 -> 83.04 | I6: =GESTÃO!J91 -> 52.238176 | J6: =GESTÃO!K91 -> 77.73 | K6: - | L6: - | M6: - | N6: - | O6: =AVERAGE(C6:N6) -> 78.116022 | P6: %
B8: REDUÇÃO DE CUSTO GERAL - R$ | C8: =C28+C52+C60+C104+C100 -> 879281.38 | Q8: total refugo/total produzidoX100
B9: Períodos | C9: Janeiro | D9: Fevereiro | E9: Março | F9: Abril | G9: Maio | H9: Junho | I9: Julho | J9: Agosto | K9: Setembro | L9: Outubro | M9: Novembro | N9: Dezembro | O9: Total
B10: Resultados | C10: =GESTÃO!D25 -> 15523.75 | D10: =GESTÃO!E25 -> 10354.75 | E10: =GESTÃO!F25 -> 6425.85 | F10: =GESTÃO!G25 -> 5685.32 | G10: =GESTÃO!H25 -> 3350 | H10: =GESTÃO!I25 -> 680 | I10: =GESTÃO!J25 -> 2977.89 | O10: =SUM(C10:N10) -> 44997.56
B12: QUALIDADE INTERNA (USIN+MONT)- PPM | C12: 4000 | Q12: total refugo/total produzidoX1000000
B13: Períodos | C13: Janeiro | D13: Fevereiro | E13: Março | F13: Abril | G13: Maio | H13: Junho | I13: Julho | J13: Agosto | K13: Setembro | L13: Outubro | M13: Novembro | N13: Dezembro
B14: Resultados | C14: =QUALIDADE!D96 -> 1517 | D14: =QUALIDADE!E96 -> 4765 | E14: =QUALIDADE!F96 -> 4350 | F14: =QUALIDADE!G96 -> 1446 | G14: =QUALIDADE!H96 -> 3317 | H14: =QUALIDADE!I96 -> 2386 | I14: - | O14: =AVERAGE(C14:N14) -> 2963.5 | P14: PPM
B16: ACIDENTES - TAXA DE GRAVIDADE - DIAS PERDIDOS | C16: 500 | Q16: total treinamentos realizados/total de treinamentos planejadosX100
B17: Períodos | C17: Janeiro | D17: Fevereiro | E17: Março | F17: Abril | G17: Maio | H17: Junho | I17: Julho | J17: Agosto | K17: Setembro | L17: Outubro | M17: Novembro | N17: Dezembro
B18: Resultados | C18: =GESTÃO!D60 -> 0 | D18: =GESTÃO!E60 -> 0 | E18: =GESTÃO!F60 -> 0 | F18: =GESTÃO!G60 -> 0 | G18: =GESTÃO!H60 -> 3729.4 | H18: 0 | I18: 0 | O18: =AVERAGE(C18:N18) -> 532.77143 | P18: Dias Perdidos
A20: COMPRAS | B20: INDICE QUALIDADE FORNECEDOR - IQF - % | C20: 90 | Q20: total de recebimentos rejeitados/total de recebimentosX100
B21: Períodos | C21: Janeiro | D21: Fevereiro | E21: Março | F21: Abril | G21: Maio | H21: Junho | I21: Julho | J21: Agosto | K21: Setembro | L21: Outubro | M21: Novembro | N21: Dezembro
B22: Resultados | C22: =COMPRAS!C58 -> 90.5 | D22: =COMPRAS!D58 -> 92.33 | E22: =COMPRAS!E58 -> 94.91 | F22: =COMPRAS!F58 -> 96.63 | G22: =COMPRAS!G58 -> 95.67 | H22: =COMPRAS!H58 -> 94.72 | I22: =COMPRAS!I58 -> - | O22: =AVERAGE(C22:I22) -> 94.126667 | P22: %
B24: ATENDIMENTO PEDIDO x ENTREGA - % | C24: 100 | Q24: total de recebimentos rejeitados/total de recebimentosX100
B25: Períodos | C25: Janeiro | D25: Fevereiro | E25: Março | F25: Abril | G25: Maio | H25: Junho | I25: Julho | J25: Agosto | K25: Setembro | L25: Outubro | M25: Novembro | N25: Dezembro
B26: Resultados | C26: =COMPRAS!C90 -> 28.304441 | D26: =COMPRAS!D90 -> 90.602114 | E26: =COMPRAS!E90 -> 102.0237 | F26: =COMPRAS!F90 -> 91.556565 | G26: =COMPRAS!G90 -> 62.276561 | H26: =COMPRAS!H90 -> 27.082549 | I26: =COMPRAS!I90 -> 27.63429 | N26: 0 | O26: =AVERAGE(C26:E26) -> 73.643418 | P26: %
B28: REDUÇÃO DE CUSTO NEGOCIAÇÃO - R$ | C28: 100000 | Q28: total de recebimentos rejeitados/total de recebimentosX100
B29: Períodos | C29: Janeiro | D29: Fevereiro | E29: Março | F29: Abril | G29: Maio | H29: Junho | I29: Julho | J29: Agosto | K29: Setembro | L29: Outubro | M29: Novembro | N29: Dezembro
B30: Resultados | C30: =COMPRAS!C25 -> 0 | D30: =COMPRAS!D25 -> 0 | E30: =COMPRAS!E25 -> 3071.1 | F30: =COMPRAS!F25 -> 2330.57 | G30: =COMPRAS!G25 -> 680 | H30: =COMPRAS!H25 -> 680 | I30: =COMPRAS!I25 -> 2977.89 | J30: =COMPRAS!J25 -> 2977.89 | ... N30: =COMPRAS!N25 -> 2977.89 | O30: =SUM(C30:N30) -> 24629.01
A32: ALMOXARIFADO | B32: ACURACIDADE DE ESTOQUE - % | C32: 95 | O32: Almox | Q32: total de itens contados/total de itens contabilizadosX100
B33: Períodos | C33: Janeiro | D33: Fevereiro | E33: Março | F33: Abril | G33: Maio | H33: Junho | I33: Julho | J33: Agosto | K33: Setembro | L33: Outubro | M33: Novembro | N33: Dezembro
B34: Resultados | N34: 0 | O34: =AVERAGE(C34:N34) -> 0 | Q34: variação de custos
B36: RUPTURA DE ESTOQUE - Nº ABSOLUTO | C36: 1
B37: Períodos | C37: Janeiro | D37: Fevereiro | E37: Março | F37: Abril | G37: Maio | H37: Junho | I37: Julho | J37: Agosto | K37: Setembro | L37: Outubro | M37: Novembro | N37: Dezembro
B38: Resultados | O38: =AVERAGE(C38:N38) -> #DIV/0! | P38: ok
B40: DIVERGÊNCIA DE RECEBIMENTO - Nº ABSOLUTO | C40: 1 | Q40: total de horas programadas mês/total hs trabalhadas mêsX100
B41: Períodos | C41: Janeiro | D41: Fevereiro | E41: Março | F41: Abril | G41: Maio | H41: Junho | I41: Julho | J41: Agosto | K41: Setembro | L41: Outubro | M41: Novembro | N41: Dezembro
B42: Resultados | N42: 0 | O42: =AVERAGE(C42:N42) -> 0
A44: QUALIDADE | B44: QUALIDADE INTERNA (USIN+MONT) - PPM | C44: 4000
B45: Períodos | C45: Janeiro | D45: Fevereiro | E45: Março | F45: Abril | G45: Maio | H45: Junho | I45: Julho | J45: Agosto | K45: Setembro | L45: Outubro | M45: Novembro | N45: Dezembro
B46: Resultados | C46: =QUALIDADE!D96 -> 1517 | D46: =QUALIDADE!E96 -> 4765 | E46: =QUALIDADE!F96 -> 4350 | F46: =F14 -> 1446 | G46: =G14 -> 3317 | H46: =H14 -> 2386 | O46: =AVERAGE(C46:N46) -> 2963.5
B48: QUALIDADE CLIENTE - PPM (SFA+ZF+VAREJO) | C48: 800
B49: Períodos | C49: Janeiro | D49: Fevereiro | E49: Março | F49: Abril | G49: Maio | H49: Junho | I49: Julho | J49: Agosto | K49: Setembro | L49: Outubro | M49: Novembro | N49: Dezembro
B50: Resultados | C50: =QUALIDADE!V96 -> 3030 | D50: =QUALIDADE!W96 -> 9797 | E50: =QUALIDADE!X96 -> 2905.5 | F50: =QUALIDADE!Y96 -> 4371 | G50: =QUALIDADE!Z96 -> 6583.5066 | H50: =QUALIDADE!AA96 -> 1557.5 | I50: =QUALIDADE!AB96 -> 5998.5 | O50: =AVERAGE(C50:N50) -> 4891.8581 | Q50: numero de não conformidade nas auditorias internas
J51: 0 | Q51: numero de não conformidade nas auditorias externas
B52: REDUÇÃO/MELHORIAS NO PROCESSO - R$ | C52: 126415
B53: Períodos | C53: Janeiro | D53: Fevereiro | E53: Março | F53: Abril | G53: Maio | H53: Junho | I53: Julho | J53: Agosto | K53: Setembro | L53: Outubro | M53: Novembro | N53: Dezembro
...

Sheet ESG - Energia Eletrica
A27: Mês | C27: Média 2025 | D27: jan | E27: fev | F27: mar | G27: abr | H27: mai | I27: jun | J27: jul | K27: ago | L27: set | M27: out | N27: nov | O27: dez | P27: Media | Q27: Res.% | R27: Totais
A28: Meta R$ | B28: 0.5 | D28: 0.5 | E28: 0.5 | F28: 0.5 | G28: 0.5 | H28: 0.5 | I28: 0.5 | J28: 0.5 | K28: 0.5 | L28: 0.5 | M28: 0.5 | N28: 0.5 | O28: 0.5
A29: Custo Mensal R$ | C29: 27725.03 | D29: 23123.92 | E29: 29137.39 | F29: 26133.29 | G29: 28243.02 | H29: 26419.66 | I29: =148.16+115.38+25294.27 -> 25557.81 | J29: =121.4+129.63+12150.3 -> 12401.33 | P29: =AVERAGE(D29:O29) -> 24430.917 | Q29: =(P29/C29)-1 -> -0.11881368 | R29: =SUM(D29:O29) -> 171016.42
A30: Consumo Mensal KWH
A31: Custo EE/peça R$ | C31: =C29/C32 -> 0.42647987 | D31: =D29/D32 -> 0.31723536 | E31: =E29/E32 -> 0.47322468 | F31: =F29/F32 -> 0.404935 | G31: =G29/G32 -> 0.44751343 | H31: =H29/H32 -> 0.46277211 | I31: =I29/I32 -> 0.68380271 | J31: =J29/J32 -> 4.0408374 | P31: =AVERAGE(D31:O31) -> 0.9757601 | Q31: =P31/C31 -> 2.2879394 | R31: =R29/R32 -> 0.47551188
A32: Peças Produzidas | C32: 65009 | D32: =GESTÃO!D92 -> 72892 | E32: =GESTÃO!E92 -> 61572 | F32: =GESTÃO!F92 -> 64537 | G32: =GESTÃO!G92 -> 63111 | H32: =GESTÃO!H92 -> 57090 | I32: 37376 | J32: 3069 | P32: =AVERAGE(D32:O32) -> 51378.143 | Q32: =(P32/C32)-1 -> -0.20967646 | R32: =SUM(D32:O32) -> 359647

Sheet ESG - Agua
A27: Mês | C27: Média 2025 | D27: jan | E27: fev | F27: mar | G27: abr | H27: mai | I27: jun | J27: jul | K27: ago | L27: set | M27: out | N27: nov | O27: dez | P27: Media | Q27: Res.% | R27: Totais
A28: Meta R$ | B28: 0.15 | D28: 0.15 | E28: 0.15 | F28: 0.15 | G28: 0.15 | H28: 0.15 | I28: 0.15 | J28: 0.15 | K28: 0.15 | L28: 0.15 | M28: 0.15 | N28: 0.15 | O28: 0.15
A29: Custo Mensal R$ | C29: 3688.89 | D29: 3804.36 | E29: 7698.6 | F29: 5061.16 | G29: 4605.48 | H29: 2251.14 | I29: 1426.82 | J29: 966.18 | P29: =AVERAGE(D29:J29) -> 3687.6771 | R29: =SUM(D29:O29) -> 25813.74
A30: Consumo Mensal m³ | D30: 102 | E30: 158 | F30: 127 | G30: 116 | H30: 94 | I30: 66 | J30: 26 | P30: =AVERAGE(D30:J30) -> 98.428571
A31: Custo Peça Produzida R$ | C31: =C29/C32 -> 0.056744297 | D31: =D29/D32 -> 0.052191736 | E31: =E29/E32 -> 0.12503411 | F31: =F29/F32 -> 0.07842261 | G31: =G29/G32 -> 0.072974283 | H31: =H29/H32 -> 0.039452156 | I31: =I29/I32 -> 0.038174765 | J31: =J29/J32 -> 0.31481916 | P31: =AVERAGE(D31:F31) -> 0.085216151 | Q31: =P31/C31-1 -> 0.5017571 | R31: =R29/R32 -> 0.071781201
A32: Peças Produzidas Unid. | C32: 65009 | D32: 72892 | E32: 61572 | F32: 64537 | G32: ='ESG - Energia Eletrica'!G32 -> 63111 | H32: 57060 | I32: 37376 | J32: 3069 | P32: =AVERAGE(D32:J32) -> 51373.857 | R32: =SUM(D32:O32) -> 359617

Sheet ESG - Resíduos
A27: Mês | C27: Média 2025 | D27: jan | E27: fev | F27: mar | G27: abr | H27: mai | I27: jun | J27: jul | K27: ago | L27: set | M27: out | N27: nov | O27: dez | P27: Media | Q27: Res.%
A28: Meta R$ | B28: 0.06 | D28: 0.06 | E28: 0.06 | F28: 0.06 | G28: 0.06 | H28: 0.06 | I28: 0.06 | J28: 0.06 | K28: 0.06 | L28: 0.06 | M28: 0.06 | N28: 0.06 | O28: 0.06
A29: Custo Descarte R$ | C29: 4020.83 | D29: 4500 | E29: 0 | F29: 0 | G29: 3600 | H29: 0 | I29: 3300 | J29: 0 | P29: =AVERAGE(D29:O29) -> 1628.5714
A30: Descarte Litros | C30: 2504 | D30: 0 | E30: 0 | F30: 2400 | G30: 0 | H30: 0 | I30: 2400 | J30: 0 | P30: 2400 | Q30: =(C30/P30)-1 -> 0.043333333
A31: Custo Peça Produzida R$ | C31: =C29/C32 -> 0.061802825 | D31: =D29/D32 -> 0.06173517 | E31: =D31 -> 0.06173517 | F31: =E31 -> 0.06173517 | G31: =G29/G32 -> 0.057042354 | H31: =H29/H32 -> 0 | I31: =I29/I32 -> 0.088291952 | J31: =J29/J32 -> 0 | P31: =P29/P32 -> 0.031697748 | Q31: =(C31/P31)-1 -> 0.94975444
A32: Peças Produzidas Unid. | C32: 65059 | D32: 72892 | E32: 61572 | F32: 64537 | G32: ='ESG - Energia Eletrica'!G32 -> 63111 | H32: 57090 | I32: 37376 | J32: 3069 | P32: =AVERAGE(D32:O32) -> 51378.143
A33: Venda Sucata Kilos | C33: 0 | D33: 45880 | E33: 29980 | F33: 45400 | G33: 37180 | H33: 0 | I33: 40220 | J33: 0
A35: Fornecedores Licenciados | D35: CADRI Nº | E35: Validade | F35: Observação
A36: PROLUMINAS
A37: EVOC
A66: Mês | C66: Média 2025 | D66: jan | E66: fev | F66: mar | G66: abr | H66: mai | I66: jun | J66: jul | K66: ago | L66: set | M66: out | N66: nov | O66: dez | P66: Media | Q66: Res.%
A67: Meta R$ | B67: 0.5 | D67: 0.5 | E67: 0.5 | F67: 0.5 | G67: 0.5 | H67: 0.5 | I67: 0.5 | J67: 0.5 | K67: 0.5 | L67: 0.5 | M67: 0.5 | N67: 0.5 | O67: 0.5
A68: Custo Mensal R$ | C68: 20699.89 | D68: 26842.61 | E68: 34664.96 | F68: 31884 | G68: 32736.19 | H68: 41520.42 | I68: 0 | J68: 0 | P68: =AVERAGE(D68:O68) -> 23949.74 | Q68: =P68/C68 -> 1.1569984
A69: Compra Mensal Litros | C69: 1200 | D69: =D79 -> 1000 | E69: =E79 -> 1200 | F69: =F79 -> 1200 | G69: =G79 -> 1200 | H69: =H79 -> 1400 | I69: =I79 -> 0 | J69: =J79 -> 0
A70: Consumo/peça produzida (L) | C70: =C69/C72 -> 0.018458983 | D70: =D69/D72 -> 0.013718927 | E70: =E69/E72 -> 0.019489378 | F70: =F69/F72 -> 0.018593985 | G70: =G69/G72 -> 0.017209729 | H70: =H69/H72 -> 0.024522683 | I70: =I69/I72 -> 0 | J70: =J69/J72 -> 0 | P70: =AVERAGE(D70:O70) -> 0.0133621
A71: Custo óleo/peça R$ | C71: =C68/C72 -> 0.31841576 | D71: =D68/D72 -> 0.3682518 | E71: =E68/E72 -> 0.56299877 | F71: =F68/F72 -> 0.49404218 | G71: =G68/G72 -> 0.46948414 | H71: =H68/H72 -> 0.72728008 | I71: =I68/I72 -> 0 | J71: =J68/J72 -> 0 | P71: =P68/P72 -> 0.45772497 | Q71: =P71/C71 -> 1.4375073
A72: Peças Produzidas Unid. | C72: 65009 | D72: 72892 | E72: 61572 | F72: 64537 | G72: 69728 | H72: 57090 | I72: 37376 | J72: 3069 | P72: =AVERAGE(D72:O72) -> 52323.429 | Q72: =P72/C72 -> 0.80486438
A74: CÓD. | B74: Descrição | C74: Média 2025 | D74: JAN/LT | E74: FEV/LT | F74: MAR/LT | G74: ABR/LT | H74: MAI/LT | I74: JUN/LT | J74: JUL/LT | K74: AGO/LT | L74: SET/LT | M74: OUT/LT | N74: NOV/LT | O74: DEZ/LT | P74: TOTAL | Q74: Média
A75: SH-30R | B75: Óleo Lubrificante | D75: 200 | E75: 200 | F75: 200 | G75: 200 | H75: 400 | I75: 0 | J75: 0 | P75: =SUM(D75:O75) -> 1200 | Q75: =AVERAGE(D75:H75) -> 240
A76: SSV-15 | B76: Óleo Lubrificante | D76: 400 | E76: 800 | F76: 800 | G76: 600 | H76: 800 | I76: 0 | J76: 0 | P76: =SUM(D76:O76) -> 3400
A77: W-98 | B77: Óleo Lubrificante | D77: 200 | E77: 0 | F77: 200 | G77: 200 | H77: 200 | I77: 0 | J77: 0 | P77: =SUM(D77:O77) -> 800
A78: BR-68 | B78: Óleo Hidraulico | D78: 200 | E78: 200 | F78: 0 | G78: 200 | H78: 0 | I78: 0 | J78: 0 | P78: =SUM(D78:O78) -> 600
A79: TOTAL | D79: =SUM(D75:D78) -> 1000 | E79: =SUM(E75:E78) -> 1200 | F79: =SUM(F75:F78) -> 1200 | G79: =SUM(G75:G78) -> 1200 | H79: =SUM(H75:H78) -> 1400 | I79: =SUM(I75:I78) -> 0 | J79: =SUM(J75:J78) -> 0 | K79: =SUM(K75:K78) -> 0 | ... O79: =SUM(O75:O78) -> 0 | P79: =SUM(D79:O79) -> 6000
A81: Fornecedores Homologados | D81: COD.FORN | E81: Validade | F81: Observação
A82: Yoshiro do Brasil
A88: 2025 | F88: 2026
A89: 2025 | B89: PROLUMINAS | F89: 20265 | G89: PROLUMINAS
A90: DATA | B90: MTR | D90: LITROS | F90: DATA | G90: MTR | I90: LITROS
A91: 03.02.25 | B91: 250004428402 | D91: 1850 | F91: 27.03.26 | G91: 260011026114 | I91: 2400
A92: 17.03.25 | B92: 250005069585 | D92: 2700 | F92: 23.06.26 | G92: 260012468269 | I92: 2400
A93: 02.04.25 | B93: 250005341738 | D93: 3500
A94: 14.04.25 | B94: 250005530031 | D94: 1600
A95: 30.04.25 | B95: 250005768434 | D95: 2000
A96: 13.05.25 | B96: 250005982056 | D96: 2000
A97: 30.03.25 | B97: 250006262892 | D97: 2900
A98: 27.06.25 | B98: 250006704487 | D98: 2200
A99: 28.08.25 | B99: 250007685790 | D99: 4200
A100: 11.09.25 | B100: 250007898157 | D100: 2400
A101: 07.10.25 | B101: 250008319430 | D101: 2300
A102: 27.10.25 | B102: 250008623690 | D102: 3600
...

Sheet ESG - S RH1
A21: Meses | B21: 2025 | C21: jan | D21: fev | E21: mar | F21: abr | G21: mai | H21: jun | I21: jul | J21: ago | K21: set | L21: out | M21: nov | N21: dez | Q21: Meses | R21: 2024 | S21: 2025 | T21: jan | U21: fev | V21: mar | W21: abr | X21: mai | Y21: jun | Z21: jul | AA21: ago | AB21: set | AC21: out | AD21: nov | AE21: dez | AF21: Média
A22: Data Solic. | B22: 0 | C22: 46024 | D22: 0 | E22: 46098 | F22: 0 | G22: 1 | H22: 1 | I22: 1 | Q22: Hs. Disp. | T22: =8010.15+1355.2 -> 9365.35 | U22: =6956.75+1232 -> 8188.75 | V22: =7523.6+1161.6 -> 8685.2 | W22: =7640+1161.6 -> 8801.6 | X22: =7317.7+1108 -> 8425.7 | Y22: =7504.3+1161.6 -> 8665.9 | Z22: =6475.2+1214.4 -> 7689.6
A23: Data Início | B23: 0 | C23: 46035 | D23: 0 | E23: 46104 | F23: 0 | G23: 1 | H23: 1 | I23: 1 | Q23: Hs. Perdas | T23: =263.5+26.4 -> 289.9 | U23: =130.15+55.6 -> 185.75 | V23: =151.5+18 -> 169.5 | W23: =141.55+20.4 -> 161.95 | X23: =243.4+85.2 -> 328.6 | Y23: =4.55+101.95 -> 106.5 | Z23: 14.4
A24: Resultado | B24: 0 | C24: =NETWORKDAYS(C22,C23,0) -> 8 | D24: =NETWORKDAYS(D22,D23,0) -> 0 | E24: =NETWORKDAYS(E22,E23,0) -> 5 | F24: =NETWORKDAYS(F22,F23,0) -> 0 | G24: =NETWORKDAYS(G22,G23,0) -> 0 | H24: =NETWORKDAYS(H22,H23,0) -> 0 | I24: =NETWORKDAYS(I22,I23,0) -> 0 | Q24: Resultado | R24: 0.022 | S24: 0.0288 | T24: =T23/T22 -> 0.030954529 | U24: =U23/U22 -> 0.02268356 | V24: =V23/V22 -> 0.019515958 | W24: =W23/W22 -> 0.018400064 | X24: =X23/X22 -> 0.038999727 | Y24: =Y23/Y22 -> 0.012289549 | Z24: =Z23/Z22 -> 0.0018726592 | AA24: =AA23/AA22 -> #DIV/0! | ... AE24: =AE23/AE22 -> #DIV/0! | AF24: =AVERAGE(T24:AE24) -> #DIV/0!
A25: Meta | C25: 20 | D25: 20 | E25: 20 | F25: 20 | G25: 20 | H25: 20 | I25: 20 | J25: 20 | K25: 20 | L25: 20 | M25: 20 | N25: 20 | Q25: Meta | T25: 0.03 | U25: 0.03 | V25: 0.03 | W25: 0.03 | X25: 0.03 | Y25: 0.03 | Z25: 0.03 | AA25: 0.03 | AB25: 0.03 | AC25: 0.03 | AD25: 0.03 | AE25: 0.03 | AF25: 0.03
A27: Nº Solicit
Q50: Meses | R50: 2024 | S50: 2025 | T50: jan | U50: fev | V50: mar | W50: abr | X50: mai | Y50: jun | Z50: jul | AA50: ago | AB50: set | AC50: out | AD50: nov | AE50: dez
A51: Meses | B51: 2025 | C51: jan | D51: fev | E51: mar | F51: abr | G51: mai | H51: jun | I51: jul | J51: ago | K51: set | L51: out | M51: nov | N51: dez | Q51: Admissão | T51: 5 | U51: 0 | V51: 2 | W51: 0 | X51: 0 | Y51: 0 | Z51: 0 | AF51: =SUM(T51:AE51) -> 7
A52: Hs Trein | C52: 98 | D52: 8 | E52: 132 | F52: 94 | G52: =42.05+225 -> 267.05 | H52: 25.25 | O52: =SUM(C52:N52) -> 624.3 | Q52: Demissão | T52: 1 | U52: 3 | V52: 3 | W52: 2 | X52: 1 | Y52: 7 | Z52: 0 | AF52: =SUM(T52:AE52) -> 17
A53: Acumulado | C53: =C52 -> 98 | D53: =D52+C53 -> 106 | E53: =E52+D53 -> 238 | F53: =F52+E53 -> 332 | G53: =G52+F53 -> 599.05 | H53: =H52+G53 -> 624.3 | Q53: Total Func | T53: =43+8 -> 51 | U53: 48 | V53: 47 | W53: =38+7 -> 45 | X53: 44 | Y53: 39 | Z53: 39 | AF53: =MEDIAN(T53:AA53) -> 45
A54: Meta | C54: 720 | D54: 720 | E54: 720 | F54: 720 | G54: 720 | H54: 720 | I54: 720 | J54: 720 | K54: 720 | L54: 720 | M54: 720 | N54: 720 | O54: =O52/C54 -> 0.86708333 | Q54: Resultado | R54: 6.94 | S54: 4.08 | T54: =(((T51+T52)/2)/T53)*100 -> 5.8823529 | U54: =(((U51+U52)/2)/U53)*100 -> 3.125 | V54: =(((V51+V52)/2)/V53)*100 -> 5.3191489 | W54: =(((W51+W52)/2)/W53)*100 -> 2.2222222 | X54: =(((X51+X52)/2)/X53)*100 -> 1.1363636 | Y54: =(((Y51+Y52)/2)/Y53)*100 -> 8.974359 | Z54: =(((Z51+Z52)/2)/Z53)*100 -> 0 | AF54: =AVERAGE(T54:AE54) -> 3.8084924
Q55: Meta | T55: 5 | U55: 5 | V55: 5 | W55: 5 | X55: 5 | Y55: 5 | Z55: 5 | AA55: 5 | AB55: 5 | AC55: 5 | AD55: 5 | AE55: 5
A76: Meses | B76: 2025 | C76: jan | D76: fev | E76: mar | F76: abr | G76: mai | H76: jun | I76: jul | J76: ago | K76: set | L76: out | M76: nov | N76: dez | O76: Média | P76: Total Ano
A77: Media R$ | B77: 3408.48 | C77: 4337.9 | D77: 3704.5 | E77: 4679.05 | F77: 4184.55 | G77: 3998.23 | H77: 2741.8 | I77: 0 | O77: =AVERAGE(C77:N77) -> 3378.0043 | P77: =SUM(C77:N77) -> 23646.03
A78: EPI's Un. | B78: 124 | C78: =SUM(C80:C90) -> 205 | D78: =SUM(D80:D90) -> 163 | E78: =SUM(E80:E90) -> 35 | F78: =SUM(F80:F90) -> 81 | G78: =SUM(G80:G91) -> 237 | H78: =SUM(H80:H91) -> 96 | I78: 0 | O78: =AVERAGE(C78:N78) -> 116.71429 | P78: =SUM(C78:N78) -> 817
D79: 720 | E79: 720 | F79: 720 | G79: 720 | H79: 720 | I79: 720 | J79: 720 | K79: 720 | L79: 720 | M79: 720 | N79: 720
A80: Sapato de Segurança | C80: 7 | D80: 4 | E80: 4 | F80: 1 | G80: 2 | H80: 0 | I80: 0 | P80: =SUM(C80:N80) -> 18
A81: Luva Petroblue CA 38792 | C81: 60 | D81: 19 | E81: 20 | F81: 40 | G81: 40 | H81: 27 | I81: 0 | P81: =SUM(C81:N81) -> 206
A82: Touca Descartável | C82: 5 | D82: 0 | E82: 0 | F82: 0 | G82: 0 | H82: 2 | I82: 0 | P82: =SUM(C82:N82) -> 7
A83: Protetor Auricular Cordinha | C83: 0 | D83: 0 | E83: 0 | F83: 0 | G83: 50 | H83: 0 | I83: 0 | P83: =SUM(C83:N83) -> 50
A84: Protetor Auricular Descartável | C84: 20 | D84: 0 | E84: 0 | F84: 0 | G84: 0 | H84: 0 | I84: 0 | P84: =SUM(C84:N84) -> 20
A85: Luva Descartável | C85: 10 | D85: 70 | E85: 10 | F85: 0 | G85: 59 | H85: 20 | I85: 0 | P85: =SUM(C85:N85) -> 169
A86: Luva Verde CA 32069 | C86: 60 | D86: 70 | E86: 0 | F86: 40 | G86: 62 | H86: 27 | I86: 0 | P86: =SUM(C86:N86) -> 259
A87: Óculos de Proteção | C87: 40 | D87: 0 | E87: 0 | F87: 0 | G87: 20 | H87: 0 | I87: 0 | P87: =SUM(C87:N87) -> 60
A88: Luva PVC Cano Longo | C88: 2 | D88: 0 | E88: 0 | F88: 0 | G88: 0 | H88: 0 | I88: 0 | P88: =SUM(C88:N88) -> 2
A89: Creme Potão | C89: 1 | D89: 0 | E89: 0 | F89: 0 | G89: 0 | H89: 20 | I89: 0 | P89: =SUM(C89:N89) -> 21
A90: Máscara Proteção | C90: 0 | D90: 0 | E90: 1 | F90: 0 | G90: 0 | H90: 0 | I90: 0 | P90: =SUM(C90:N90) -> 1
A91: Palmilha PU | C91: 0 | D91: 0 | E91: 0 | F91: 0 | G91: 4 | H91: 0 | I91: 0 | P91: =SUM(C91:N91) -> 4

Sheet GESTÃO
A22: Mês | D22: jan | E22: fev | F22: mar | G22: abr | H22: mai | I22: jun | J22: jul | K22: ago | L22: set | M22: out | N22: nov | O22: dez | P22: Total R$ | Q22: Res.%
A23: Meta | B23: =[2]Resultados!$C$8 -> 1529281.4 | D23: =[2]Resultados!$C$8 -> 1529281.4 | E23: =[2]Resultados!$C$8 -> 1529281.4 | F23: =[2]Resultados!$C$8 -> 1529281.4 | G23: =[2]Resultados!$C$8 -> 1529281.4 | H23: =[2]Resultados!$C$8 -> 1529281.4 | I23: =[2]Resultados!$C$8 -> 1529281.4 | J23: =[2]Resultados!$C$8 -> 1529281.4 | K23: =[2]Resultados!$C$8 -> 1529281.4 | ... O23: =[2]Resultados!$C$8 -> 1529281.4
A24: Previsão Redução Mes R$ | D24: 74592
A25: Redução Mensal R$ | D25: =12169+PROCESSOS!C24 -> 15523.75 | E25: =7000+PROCESSOS!D24 -> 10354.75 | F25: =3071.1+PROCESSOS!E24 -> 6425.85 | G25: =PROCESSOS!F24+COMPRAS!F25 -> 5685.32 | H25: =MANUTENÇÃO!G25 -> 3350 | I25: =COMPRAS!H25 -> 680 | J25: =COMPRAS!I25 -> 2977.89 | K25: =COMPRAS!J25 -> 2977.89 | L25: =COMPRAS!K25 -> 2977.89 | M25: =COMPRAS!L25 -> 2977.89 | N25: =COMPRAS!M25 -> 2977.89 | O25: =COMPRAS!N25 -> 2977.89 | P25: =SUM(D25:O25) -> 59887.01 | Q25: =(P25/B23)*100 -> 3.916023
A26: Redução Acumulada R$ | D26: =D25 -> 15523.75 | E26: =D26+E25 -> 25878.5 | F26: =E26+F25 -> 32304.35 | G26: =F26+G25 -> 37989.67 | H26: =G26+H25 -> 41339.67 | I26: =H26+I25 -> 42019.67 | J26: =I26+J25 -> 44997.56 | K26: =J26+K25 -> 47975.45 | L26: =K26+L25 -> 50953.34 | ... O26: =N26+O25 -> 59887.01
A27: Percentual % | D27: =(D26/D23)*100 -> 1.015101 | E27: =(E26/E23)*100 -> 1.6922 | F27: =(F26/F23)*100 -> 2.1123876 | G27: =(G26/G23)*100 -> 2.4841517 | H27: =(H26/H23)*100 -> 2.7032089 | I27: =(I26/I23)*100 -> 2.7476742 | J27: =(J26/J23)*100 -> 2.942399 | K27: =(K26/K23)*100 -> 3.1371238 | ... O27: =(O26/O23)*100 -> 3.916023
A28: Descrição da redução | D28: Unidade Hidráulica / Reuso Ferramentas | E28: Lub.Ext.4ºeixo / Reuso Ferramentas | F28: Redução Compra Ferramentas / Reuso Ferramentas | G28: Reuso Ferramentas + Vlr cestabásica e Derivados | H28: Manut.Interna Compressor
Q44: Conforme - NBR14283:2023
Q46: Taxa de gravidade
Q48: (dias perdidos)
Q50: Até 500 | R50: MUITO BOA
Q51: De 500,01 - 1000 | R51: BOA
Q52: De 1000,01 - 2000 | R52: REGULAR
Q53: Acima de 2000 | R53: PÉSSIMA
A58: Mês | D58: jan | E58: fev | F58: mar | G58: abr | H58: mai | I58: jun | J58: jul | K58: ago | L58: set | M58: out | N58: nov | O58: dez | P58: Media | Q58: Res.%
A59: Meta | B59: 500 | D59: 500 | E59: 500 | F59: 500 | G59: 500 | H59: 500 | I59: 500 | J59: 500 | K59: 500 | L59: 500 | M59: 500 | N59: 500 | O59: 500
A60: Resultado Mensal | D60: 0 | E60: 0 | F60: 0 | G60: 0 | H60: 3729.4 | I60: 0 | J60: 0 | P60: =AVERAGE(D60:O60) -> 532.77143 | Q60: =(P60/B59)*100 -> 106.55429
A61: Horas Trabalhadas | D61: 7329.93 | E61: 6690.36 | F61: 7211.03 | G61: 7250.77 | H61: 7239.77 | I61: 6841.95 | J61: 867.7
A88: Mês | C88: Média 2025 | D88: jan | E88: fev | F88: mar | G88: abr | H88: mai | I88: jun | J88: jul | K88: ago | L88: set | M88: out | N88: nov | O88: dez | P88: Media | Q88: Res.%
A89: Meta % | B89: 90 | D89: 90 | E89: 90 | F89: 90 | G89: 90 | H89: 90 | I89: 90 | J89: 90 | K89: 90 | L89: 90 | M89: 90 | N89: 90 | O89: 90
A90: Resultado Mensal % | C90: 59.39 | D90: 60.47 | E90: 61.5 | F90: 61.66 | G90: 64.57 | H90: 57.89 | I90: 61.59 | J90: 26.24 | K90: 53.28 | P90: =AVERAGE(D90:O90) -> 55.9 | Q90: =(P90/B89)*100 -> 62.111111
A91: Resultado Mensal % (PerfxQual) | D91: 83.19 | E91: 81.54 | F91: 82.13 | G91: 83.45 | H91: 81.61 | I91: 83.04 | J91: =(0.5228*0.9992)*100 -> 52.238176 | K91: 77.73 | P91: =AVERAGE(D91:O91) -> 78.116022 | Q91: =(P91/B89)*100 -> 86.79558
A92: Peças Produzidas Unid. | D92: 72892 | E92: 61572 | F92: 64537 | G92: 63111 | H92: 57090 | I92: 37376 | J92: 3069 | K92: 23085 | P92: =AVERAGE(D92:O92) -> 47841.5 | Q92: =SUM(D92:O92) -> 382732

Sheet Plano de Ação
B2: Plano de Ação
B4: #VALUE! | D4: Área:Produção | H4: Responsável: | K4: =COUNTA(K8:K22) -> 0
D5: Data de atualização: | G5: N° seqüencial do projeto: NA | K5: =COUNTA(C8:C22) -> 0
D6: Título: Produtividade | G6: Local: | I6: Hora:
B7: Processo | C7: Ações | D7: O que Fazer? (objetivo) | E7: Quem irá fazer? (responsável) | F7: Quando? (cronograma) | G7: Onde Fazer? (local) | H7: Por que Fazer? (motivo) | I7: Como Fazer? (processo) | J7: Quanto para fazer? (custo) | K7: Status
B24: Participantes/Backup: | D24: Orientações Preenchimento: 1) O que (inicia com um verbo no infinitivo, no sentido de "fazer / executar") 2) Quem: apenas um nome. Não vale colocar "Equipe XYZ", "Área Z". 3) Quando: dd/mm/aaaa 4) Onde: indicar área, setor, máquina, local, etc 5) Por que: o que justifique

Sheet COMPRAS
X3: AGOSTO P FRENTE | Y3: 455 | Z3: AO3
X4: JULHO A SETEMBRO | Y4: 205 | Z4: SPIVIT
X5: JULHO A DEZEMBRO | Y5: 600 | Z5: GF
X6: JULHO A DEZEMBRO | Y6: 300 | Z6: MKT
X7: MAIO P FRENTE | Y7: 87.9 | Z7: PANDA VÍDEO
X8: MAIO P FRENTE | Y8: 69.99 | Z8: PLATAFORMA TI
X9: JULHO A DEZEMBRO | Y9: 200 | Z9: PREÇO SOFT
X10: JUNHO A DEZEMBRO | Y10: 200 | Z10: UNICODE
X11: MAIO P FRENTE | Y11: 600 | Z11: CESTA BASICA
X12: MAIO P FRENTE | Y12: 80 | Z12: COPA
Y13: =SUM(Y2:Y12) -> 2797.89
A22: Mês | C22: jan | D22: fev | E22: mar | F22: abr | G22: mai | H22: jun | I22: jul | J22: ago | K22: set | L22: out | M22: nov | N22: dez | O22: Total R$ | P22: Res.%
A23: Meta | B23: =[2]Resultados!$C$28 -> 750000
A24: Previsão Red. Mês R$
A25: Redução Mês R$ | C25: 0 | D25: 0 | E25: 3071.1 | F25: 2330.57 | G25: 680 | H25: 680 | I25: 2977.89 | J25: 2977.89 | K25: 2977.89 | L25: 2977.89 | M25: 2977.89 | N25: 2977.89 | O25: =SUM(C25:N25) -> 24629.01 | P25: =(O25/B23)*100 -> 3.283868
A26: Redução Acum. R$ | C26: 0 | D26: 0 | E26: =D26+E25 -> 3071.1 | F26: =E26+F25 -> 5401.67 | G26: =F26+G25 -> 6081.67 | H26: =G26+H25 -> 6761.67 | I26: =H26+I25 -> 9739.56 | J26: =I26+J25 -> 12717.45 | K26: =J26+K25 -> 15695.34 | L26: =K26+L25 -> 18673.23 | ... N26: =M26+N25 -> 24629.01
A27: Percentual % | C27: =(C26/C23)*100 -> #DIV/0! | D27: =(D26/D23)*100 -> #DIV/0! | E27: =E25/B23*100 -> 0.40948 | F27: =(F26/F23)*100 -> #DIV/0!
A28: Descrição da redução | E28: Redução Vlr. Compra Ferramenta | F28: Redução Vlr Cesta básica de seus Derivados na fábrica
A56: Mês | C56: jan | D56: fev | E56: mar | F56: abr | G56: mai | H56: jun | I56: jul | J56: ago | K56: set | L56: out | M56: nov | N56: dez | O56: Média | P56: Res.%
A57: Meta | B57: 90 | C57: 90 | D57: 90 | E57: 90 | F57: 90 | G57: 90 | H57: 90 | I57: 90 | J57: 90 | K57: 90 | L57: 90 | M57: 90 | N57: 90
A58: IQF Geral | C58: 90.5 | D58: 92.33 | E58: 94.91 | F58: 96.63 | G58: 95.67 | H58: 94.72 | I58: - | O58: =AVERAGE(C58:N58) -> 94.126667 | P58: =(O58/B57)*100 -> 104.58519
A59: Qualidade | C59: 100 | D59: 100 | E59: 95 | O59: =AVERAGE(C59:N59) -> 98.333333
A60: Refugo | C60: 60 | D60: 87 | E60: 70 | O60: =AVERAGE(C60:N60) -> 72.333333
A61: Entrega | C61: 100 | D61: 96 | E61: 80 | O61: =AVERAGE(C61:N61) -> 92
A62: Resultado % | C62: =C58/B57 -> 1.0055556 | D62: =D58/B57 -> 1.0258889 | E62: =E58/B57 -> 1.0545556
A86: Mês | C86: jan | D86: fev | E86: mar | F86: abr | G86: mai | H86: jun | I86: jul | J86: ago | K86: set | L86: out | M86: nov | N86: dez | O86: Média | P86: Res.%
A87: Meta | B87: 1 | C87: 100 | D87: 100 | E87: 100 | F87: 100 | G87: 100 | H87: 100 | I87: 100 | J87: 100 | K87: 100 | L87: 100 | M87: 100 | N87: 100
A88: Pedido Colocado Unid | C88: 516290 | D88: 155801 | E88: 672828 | F88: 143579 | G88: 195523 | H88: 443459 | I88: 39802 | O88: =AVERAGE(C88:N88) -> 309611.71
A89: Entrega Recebida Unid. | C89: 146133 | D89: 141159 | E89: 686444 | F89: 131456 | G89: 121765 | H89: 120100 | I89: 10999 | O89: =AVERAGE(C89:N89) -> 194008
A90: Resultado % | C90: =C89/C88*100 -> 28.304441 | D90: =D89/D88*100 -> 90.602114 | E90: =E89/E88*100 -> 102.0237 | F90: =F89/F88*100 -> 91.556565 | G90: =G89/G88*100 -> 62.276561 | H90: =H89/H88*100 -> 27.082549 | I90: =I89/I88*100 -> 27.63429 | O90: =AVERAGE(C90:I90) -> 61.354317

Sheet ALMOXARIFADO
A22: Mês | C22: jan | D22: fev | E22: mar | F22: abr | G22: mai | H22: jun | I22: jul | J22: ago | K22: set | L22: out | M22: nov | N22: dez | O22: Média | P22: Res.%
A23: Meta | B23: 0.95 | C23: 0.95 | D23: 0.95 | E23: 0.95 | F23: 0.95 | G23: 0.95 | H23: 0.95 | I23: 0.95 | J23: 0.95 | K23: 0.95 | L23: 0.95 | M23: 0.95 | N23: 0.95
A24: Qtde Inventariada | O24: =AVERAGE(C24:N24) -> #DIV/0! | P24: =O26/B23 -> #DIV/0!
A25: Resultado encontrado | O25: =AVERAGE(C25:N25) -> #DIV/0!
A26: Percentual % | O26: =O25/O24 -> #DIV/0!
A27: Descrição dos itens
A52: Mês | C52: jan | D52: fev | E52: mar | F52: abr | G52: mai | H52: jun | I52: jul | J52: ago | K52: set | L52: out | M52: nov | N52: dez | O52: Média | P52: Res.%
A53: Meta | B53: 1 | C53: 1 | D53: 1 | E53: 1 | F53: 1 | G53: 1 | H53: 1 | I53: 1 | J53: 1 | K53: 1 | L53: 1 | M53: 1 | N53: 1
A54: Falta de Produto | O54: =AVERAGE(C54:N54) -> #DIV/0! | P54: =O56/B53 -> 0
A57: Descrição dos itens
A78: Mês | C78: jan | D78: fev | E78: mar | F78: abr | G78: mai | H78: jun | I78: jul | J78: ago | K78: set | L78: out | M78: nov | N78: dez | O78: Média | P78: Res.%
A79: Meta | B79: 1 | C79: 1 | D79: 1 | E79: 1 | F79: 1 | G79: 1 | H79: 1 | I79: 1 | J79: 1 | K79: 1 | L79: 1 | M79: 1 | N79: 1
A80: Divergência encont | O80: =AVERAGE(C80:N80) -> #DIV/0!
A81: Descrição dos itens
A104: Deposito | B104: Mês | C104: jan | D104: fev | E104: mar | F104: abr | G104: mai | H104: jun | I104: jul | J104: ago | K104: set | L104: out | M104: nov | N104: dez | O104: Média | Q104: Deposito | R104: Mês | S104: jan | T104: fev | U104: mar | V104: abr | W104: mai | X104: jun | Y104: jul | Z104: ago | AA104: set | AB104: out | AC104: nov | AD104: dez | AE104: Média
A105: DEP01 - almox | C105: 385534 | D105: 481224 | E105: 389322 | F105: 360414 | G105: 426680 | H105: =522798+5760 -> 528558 | I105: 0 | J105: 725809 | O105: =AVERAGE(C105:N105) -> 412192.62 | Q105: DEP01 - almox | S105: 751759.71 | T105: 822965.15 | U105: 794264.07 | V105: 648195.51 | W105: 625437.04 | X105: 466627.22 | Y105: 0 | Z105: 654343.42 | AE105: =AVERAGE(S105:AD105) -> 595449.01
A106: DEP02 - produção | C106: 10985 | D106: 10384 | E106: 16891 | F106: 19925 | G106: 28497 | H106: 4905 | I106: 0 | J106: 28340 | O106: =AVERAGE(C106:N106) -> 14990.875 | Q106: DEP02 - produção | S106: 107095.41 | T106: 122335.33 | U106: 192951.12 | V106: 235746.6 | W106: 339002.14 | X106: 57194.98 | Y106: 0 | Z106: 280675.61 | AE106: =AVERAGE(S106:AD106) -> 166875.15
A107: DEP03 | O107: =AVERAGE(C107:N107) -> #DIV/0! | Q107: DEP03 | AE107: =AVERAGE(S107:AD107) -> #DIV/0!
A108: DEP04 | O108: =AVERAGE(C108:N108) -> #DIV/0! | Q108: DEP04 | AE108: =AVERAGE(S108:AD108) -> #DIV/0!
A109: DEP05 | O109: =AVERAGE(C109:N109) -> #DIV/0! | Q109: DEP05 | AE109: =AVERAGE(S109:AD109) -> #DIV/0!
A110: DEP06 | O110: =AVERAGE(C110:N110) -> #DIV/0! | Q110: DEP06 | AE110: =AVERAGE(S110:AD110) -> #DIV/0!
A111: DEP07 - ferramentas | C111: 2839 | D111: 2784 | E111: 2855 | F111: 2736 | G111: 2683 | H111: 2689 | I111: 0 | J111: 2604 | O111: =AVERAGE(C111:N111) -> 2398.75 | Q111: DEP07 - ferramentas | S111: 424208.71 | T111: 396651.04 | U111: 390116.54 | V111: 378325.63 | W111: 377306.89 | X111: 383350.93 | Y111: 0 | Z111: 370101.69 | AE111: =AVERAGE(S111:AD111) -> 340007.68
A112: DEP08 - evl varejo | C112: 80843 | D112: 81069 | E112: 79528 | F112: 78865 | G112: 81909 | H112: 79860 | I112: 0 | J112: 78721 | O112: =AVERAGE(C112:N112) -> 70099.375 | Q112: DEP08 - evl varejo | S112: 0 | T112: 0 | U112: 0 | V112: 0 | W112: 0 | X112: 5575542.2 | Y112: 0 | Z112: 5507997.4 | AE112: =AVERAGE(S112:AD112) -> 1385442.5
A113: DEP09 - intermed | C113: 5085 | D113: 7375 | E113: 9146 | F113: 11547 | G113: 10091 | H113: 4122 | I113: 0 | J113: 3394 | O113: =AVERAGE(C113:N113) -> 6345 | Q113: DEP09 - intermed | S113: 41557.21 | T113: 68884.51 | U113: 52680.33 | V113: 106034.7 | W113: 85871.89 | X113: 34309.58 | Y113: 0 | Z113: 24597.48 | AE113: =AVERAGE(S113:AD113) -> 51741.963
A114: DEP10 - Montag | C114: 157409 | D114: 181585 | E114: =173805+1651 -> 175456 | F114: 145125 | G114: 162764 | H114: 191244 | I114: 0 | J114: 199683 | O114: =AVERAGE(C114:N114) -> 151658.25 | Q114: DEP10 - Montag | S114: 261347.87 | T114: 165682.64 | U114: =21591.31+156965.82 -> 178557.13 | V114: 139978.03 | W114: 144182.53 | X114: 248911.53 | Y114: 0 | Z114: 209537.72 | AE114: =AVERAGE(S114:AD114) -> 168524.68
A115: DEP11 - global | C115: 621762 | D115: 433100 | E115: 427615 | F115: 408961 | G115: 404271 | H115: 0 | I115: 0 | J115: 0 | O115: =AVERAGE(C115:N115) -> 286963.62 | Q115: DEP11 - global | S115: 397257.24 | T115: 219183.97 | U115: 212151.57 | V115: 202926.65 | W115: 197496.87 | Y115: 0 | Z115: 0 | AE115: =AVERAGE(S115:AD115) -> 175573.76
A116: DEP12 - fer produção | C116: 359 | D116: 391 | E116: 366 | F116: 420 | G116: 460 | H116: 395 | I116: 0 | J116: 421 | O116: =AVERAGE(C116:N116) -> 351.5 | Q116: DEP12 - fer produção | S116: 59814.78 | T116: 63916.62 | U116: 57257.43 | V116: 60925.51 | W116: 57607.02 | X116: 51104.16 | Y116: 0 | Z116: 53099.26 | AE116: =AVERAGE(S116:AD116) -> 50465.598
A117: DEP13 - exportaç | C117: 1970 | D117: 0 | E117: 0 | F117: 0 | G117: 300 | H117: 0 | I117: 0 | J117: 0 | O117: =AVERAGE(C117:N117) -> 283.75 | Q117: DEP13 - exportaç | S117: 0 | T117: 0 | U117: 0 | V117: 0 | W117: 1744.03 | Y117: 0 | Z117: 0 | AE117: =AVERAGE(S117:AD117) -> 249.14714
A118: Total | C118: =SUM(C105:C117) -> 1266786 | D118: =SUM(D105:D117) -> 1197912 | E118: =SUM(E105:E117) -> 1101179 | F118: =SUM(F105:F117) -> 1027993 | G118: =SUM(G105:G117) -> 1117655 | H118: =SUM(H105:H117) -> 811773 | I118: =SUM(I105:I117) -> 0 | J118: =SUM(J105:J117) -> 1038972 | Q118: Total | S118: =SUM(S105:S117) -> 2043040.9 | T118: =SUM(T105:T117) -> 1859619.3 | U118: =SUM(U105:U117) -> 1877978.2 | V118: =SUM(V105:V117) -> 1772132.6 | W118: =SUM(W105:W117) -> 1828648.4 | X118: =SUM(X105:X117) -> 6817040.6 | Y118: =SUM(Y105:Y117) -> 0 | Z118: =SUM(Z105:Z117) -> 7100352.6 | AE118: 1926879.5
AK121: FERRAMENTAS
AK122: Fornecedores | AL122: jan | AM122: fev | AN122: mar | AO122: abr | AP122: mai | AQ122: jun | AR122: jul | AS122: ago | AT122: set | AU122: out | AV122: nov | AW122: dez | AX122: Média | AY122: Total
AK123: DN | AL123: 0 | AM123: 1630 | AN123: 1184 | AO123: 4189 | AP123: 1210 | AQ123: 8595 | AR123: 960 | AX123: =AVERAGE(AL123:AW123) -> 2538.2857 | AY123: =SUM(AL123:AW123) -> 17768
AK124: DR | AL124: 13339 | AM124: 14698 | AN124: 13515 | AO124: 8701 | AP124: 11870 | AQ124: 9798 | AR124: 0 | AX124: =AVERAGE(AL124:AW124) -> 10274.429 | AY124: =SUM(AL124:AW124) -> 71921
AK125: VN | AL125: 3645 | AM125: 6157 | AN125: =7990 -> 7990 | AO125: 7590 | AP125: 2356 | AQ125: 5292.5 | AR125: 1658 | AX125: =AVERAGE(AL125:AW125) -> 4955.5 | AY125: =SUM(AL125:AW125) -> 34688.5
AK126: VR | AL126: 6910 | AM126: 9788.48 | AN126: 9148.01 | AO126: 10983.88 | AP126: 10580 | AQ126: 5922.93 | AR126: 2068.9 | AX126: =AVERAGE(AL126:AW126) -> 7914.6 | AY126: =SUM(AL126:AW126) -> 55402.2
AK127: WOLF | AL127: 2042.6 | AM127: 2878.13 | AN127: 3228.26 | AO127: 3479.6 | AP127: 875.4 | AQ127: 829.85 | AR127: 1049.24 | AX127: =AVERAGE(AL127:AW127) -> 2054.7257 | AY127: =SUM(AL127:AW127) -> 14383.08
AK128: MCTOOLS | AL128: 301.5 | AM128: 4594.46 | AN128: 2778.59 | AO128: 1905 | AP128: 0 | AQ128: 786.9 | AR128: 0 | AX128: =AVERAGE(AL128:AW128) -> 1480.9214 | AY128: =SUM(AL128:AW128) -> 10366.45
AK129: ANAHNG | AL129: 0 | AM129: 112.39 | AN129: 0 | AO129: 0 | AP129: 0 | AQ129: 0 | AR129: 0 | AX129: =AVERAGE(AL129:AW129) -> 16.055714 | AY129: =SUM(AL129:AW129) -> 112.39
AK130: BRUNITEC | AL130: 7718.16 | AM130: 5788.62 | AN130: 5788.62 | AO130: 0 | AP130: 3039.61 | AQ130: 7503.76 | AR130: 0 | AX130: =AVERAGE(AL130:AW130) -> 4262.6814 | AY130: =SUM(AL130:AW130) -> 29838.77
AK131: EMUGE | AL131: 1834.54 | AM131: 0 | AN131: 0 | AO131: 0 | AP131: 0 | AQ131: 0 | AR131: 0 | AX131: =AVERAGE(AL131:AW131) -> 262.07714 | AY131: =SUM(AL131:AW131) -> 1834.54
...

Sheet QUALIDADE
A22: Mês | D22: jan | E22: fev | F22: mar | G22: abr | H22: mai | I22: jun | J22: jul | K22: ago | L22: set | M22: out | N22: nov | O22: dez | P22: Total R$ | Q22: Res.%
A23: Meta | B23: =[2]Resultados!$C$52 -> 126415 | D23: 126415 | E23: 126415 | F23: 126415 | G23: 126415 | H23: 126415 | I23: 126415 | J23: 126415 | K23: 126415 | L23: 126415 | M23: 126415 | N23: 126415 | O23: 126415
A24: Previsão Redução Mês R$ | D24: 0 | E24: 0 | F24: 0 | G24: 0 | H24: 0 | I24: 0 | J24: 0 | K24: 0 | L24: 0 | M24: 0 | N24: 0 | O24: 0 | P24: 0
A25: Redução R$ | D25: 0 | E25: 0 | F25: 0 | G25: 0 | H25: 0 | I25: 0 | J25: 0 | K25: 0 | L25: 0 | M25: 0 | N25: 0 | O25: 0 | P25: =SUM(D25:O25) -> 0 | Q25: =(P25/B23)*100 -> 0
A26: Redução Acumulada R$ | D26: =D25 -> 0 | E26: =D26+E25 -> 0 | F26: =E26+F25 -> 0 | G26: =F26+G25 -> 0 | H26: =G26+H25 -> 0 | I26: =H26+I25 -> 0 | J26: =I26+J25 -> 0 | K26: =J26+K25 -> 0 | L26: =K26+L25 -> 0 | ... O26: =N26+O25 -> 0
A27: Percentual % | D27: =(D26/D23)*100 -> 0 | E27: =(E26/E23)*100 -> 0 | F27: =(F26/F23)*100 -> 0 | G27: =(G26/G23)*100 -> 0
A28: Descrição
A56: Mês | D56: jan | E56: fev | F56: mar | G56: abr | H56: mai | I56: jun | J56: jul | K56: ago | L56: set | M56: out | N56: nov | O56: dez | P56: Totais | Q56: Méd.% | T56: Mês | V56: jan | W56: fev | X56: mar | Y56: abr | Z56: mai | AA56: jun | AB56: jul | AC56: ago | AD56: set | AE56: out | AF56: nov | AG56: dez | AH56: Total R$ | AI56: Res.% | AL56: Mês | AN56: jan | AO56: fev | AP56: mar | AQ56: abr | AR56: mai | AS56: jun | AT56: jul | AU56: ago | AV56: set | AW56: out | AX56: nov | AY56: dez | AZ56: Total R$ | BA56: Res.%
A57: Meta | B57: 0.015 | D57: 0.015 | E57: 0.015 | F57: 0.015 | G57: 0.015 | H57: 0.015 | I57: 0.015 | J57: 0.015 | K57: 0.015 | L57: 0.015 | M57: 0.015 | N57: 0.015 | O57: 0.015 | T57: Meta | U57: 0.015 | V57: 0.015 | W57: 0.015 | X57: 0.015 | Y57: 0.015 | Z57: 0.015 | AA57: 0.015 | AB57: 0.015 | AC57: 0.015 | AD57: 0.015 | AE57: 0.015 | AF57: 0.015 | AG57: 0.015 | AL57: Meta | AM57: 0.015 | AN57: 0.015 | AO57: 0.015 | AP57: 0.015 | AQ57: 0.015 | AR57: 0.015 | AS57: 0.015 | AT57: 0.015 | AU57: 0.015 | AV57: 0.015 | AW57: 0.015 | AX57: 0.015 | AY57: 0.015
A58: Devolução Itens | D58: 13 | E58: 28 | F58: 14 | G58: 18 | H58: 19 | I58: 4 | J58: 21 | P58: =SUM(D58:O58) -> 117 | T58: ZF Brasil | V58: 0 | W58: 0 | X58: 0 | Y58: 0 | Z58: 0 | AA58: 0 | AB58: 0 | AH58: =SUM(V58:AG58) -> 0 | AI58: =AH61/U57 -> 0.01320709 | AL58: Varejo | AN58: =D60 -> 0.0078740157 | AO58: =E60 -> 0.019594122 | AP58: =F60 -> 0.0058115401 | AQ58: =G60 -> 0.0087421078 | AR58: =H60 -> 0.013167013 | AS58: =I58 -> 4 | AT58: =J58 -> 21 | AU58: =K58 -> 0 | AV58: =L58 -> 0 | AW58: =M58 -> 0 | AX58: =N58 -> 0 | AY58: =O58 -> 0 | AZ58: =SUM(AN58:AY58) -> 25.055189
A59: Total de Itens Vendidos | D59: 1651 | E59: 1429 | F59: 2409 | G59: 2059 | H59: 1443 | I59: 1281 | J59: 1780 | P59: =SUM(D59:O59) -> 12052 | T59: SFA | V59: 11 | W59: 10 | X59: 8 | Y59: 21 | Z59: 9 | AA59: 4 | AB59: - | AH59: =SUM(V59:AG59) -> 63 | AL59: Mercado | AN59: =V61 -> 0.00022196662 | AO59: =W61 -> 0.00016895888 | AP59: =X61 -> 0.00013750193 | AQ59: =Y61 -> 0.00034835114 | AR59: =Z61 -> 0.00015772871 | AS59: =AA60 -> 33743 | AT59: =AB60 -> 0 | AU59: =AC60 -> 0 | AV59: =AD60 -> 0 | AW59: =AE60 -> 0 | AX59: =AF60 -> 0 | AY59: =AG60 -> 0 | AZ59: =SUM(AN59:AY59) -> 33743.001 | BA59: =AZ59/AZ58 -> 1346.747
A60: Percentual % | D60: =D58/D59 -> 0.0078740157 | E60: =E58/E59 -> 0.019594122 | F60: =F58/F59 -> 0.0058115401 | G60: =G58/G59 -> 0.0087421078 | H60: =H58/H59 -> 0.013167013 | I60: =I58/I59 -> 0.0031225605 | J60: =J58/J59 -> 0.011797753 | Q60: =AVERAGE(D60:O60) -> 0.010015587 | T60: Total Vendas | V60: 49557 | W60: 59186 | X60: 58181 | Y60: 60284 | Z60: 57060 | AA60: =25446+8297 -> 33743 | AB60: =SUM(AB58:AB59) -> 0 | AC60: =SUM(AC58:AC59) -> 0 | AD60: =SUM(AD58:AD59) -> 0 | AE60: =SUM(AE58:AE59) -> 0 | AF60: =SUM(AF58:AF59) -> 0 | AG60: =SUM(AG58:AG59) -> 0 | AH60: =SUM(V60:AG60) -> 318011 | AL60: Mèdia | AN60: =AVERAGE(AN58:AN59) -> 0.0040479912 | AO60: =AVERAGE(AO58:AO59) -> 0.0098815403 | AP60: =AVERAGE(AP58:AP59) -> 0.002974521 | AQ60: =AVERAGE(AQ58:AQ59) -> 0.0045452295 | AR60: =AVERAGE(AR58:AR59) -> 0.0066623709 | AS60: =SUM(AS58:AS59) -> 33747 | AT60: =SUM(AT58:AT59) -> 21 | AU60: =SUM(AU58:AU59) -> 0 | AV60: =SUM(AV58:AV59) -> 0 | AW60: =SUM(AW58:AW59) -> 0 | AX60: =SUM(AX58:AX59) -> 0 | AY60: =SUM(AY58:AY59) -> 0 | AZ60: =SUM(AZ58:AZ59) -> 33768.056
A61: Descrição | T61: % Reclamação | V61: =(V59/V60) -> 0.00022196662 | W61: =(W59/W60) -> 0.00016895888 | X61: =(X59/X60) -> 0.00013750193 | Y61: =(Y59/Y60) -> 0.00034835114 | Z61: =(Z59/Z60) -> 0.00015772871 | AA61: =(AA59/AA60) -> 0.00011854311 | AB61: - | AH61: =(AH59/AH60) -> 0.00019810635
AM66: ⭐ Ótimo: < 1%
AM67: 👍 Aceitável: 1% a 3%
AM68: ⚠️ Atenção: > 3%
A91: Mês | C91: 2025 | D91: jan | E91: fev | F91: mar | G91: abr | H91: mai | I91: jun | J91: jul | K91: ago | L91: set | M91: out | N91: nov | O91: dez | P91: PPM | Q91: Res.% | T91: Mês | V91: jan | W91: fev | X91: mar | Y91: abr | Z91: mai | AA91: jun | AB91: jul | AC91: ago | AD91: set | AE91: out | AF91: nov | AG91: dez | AH91: PPM | AI91: Res.%
A92: Meta | B92: 4000 | D92: 4000 | E92: 4000 | F92: 4000 | G92: 4000 | H92: 4000 | I92: 4000 | J92: 4000 | K92: 4000 | L92: 4000 | M92: 4000 | N92: 4000 | O92: 4000 | T92: Meta | U92: 800 | V92: 800 | W92: 800 | X92: 800 | Y92: 800 | Z92: 800 | AA92: 800 | AB92: 800 | AC92: 800 | AD92: 800 | AE92: 800 | AF92: 800 | AG92: 800
A93: PPM Usinagem | C93: 3917 | D93: 3034 | E93: 2680 | F93: 4974 | G93: 2772 | H93: 2576 | I93: 4772 | J93: - | P93: =AVERAGE(D93:O93) -> 3468 | Q93: =P96/B92 -> 0.740875 | T93: PPM ZF Brasil | V93: 0 | W93: 0 | X93: 0 | Y93: 0 | Z93: 0 | AA93: 0 | AB93: 0 | AH93: =AVERAGE(V93:AG93) -> 0 | AI93: =AH96/U92 -> 6.1148226
A94: PPM Montagem | D94: 0 | E94: 6850 | F94: 3726 | G94: 120 | H94: 4058 | I94: 0 | J94: - | P94: =AVERAGE(D94:O94) -> 2459 | T94: PPM SFA | V94: 155 | W94: 162 | X94: 124 | Y94: 332.6 | Z94: 158 | AA94: 0 | AB94: 0 | AH94: =AVERAGE(V94:AG94) -> 133.08571
A95: PPM Total | D95: =SUM(D93:D94) -> 3034 | E95: =SUM(E93:E94) -> 9530 | F95: =SUM(F93:F94) -> 8700 | G95: =SUM(G93:G94) -> 2892 | H95: =SUM(H93:H94) -> 6634 | I95: =SUM(I93:I94) -> 4772 | J95: - | P95: =SUM(D95:O95) -> 35562 | T95: PPM Varejo | V95: 6060 | W95: 19594 | X95: 5811 | Y95: 8742 | Z95: =(H58/H59)*1000000 -> 13167.013 | AA95: 3115 | AB95: 11997 | AH95: =SUM(V95:AG95) -> 68486.013
A96: PPM Médio | D96: =AVERAGE(D93:D94) -> 1517 | E96: =AVERAGE(E93:E94) -> 4765 | F96: =AVERAGE(F93:F94) -> 4350 | G96: =AVERAGE(G93:G94) -> 1446 | H96: =AVERAGE(H93:H94) -> 3317 | I96: =AVERAGE(I93:I94) -> 2386 | J96: - | P96: =AVERAGE(D96:O96) -> 2963.5 | T96: PPM Médio | V96: =V95/2 -> 3030 | W96: =W95/2 -> 9797 | X96: =X95/2 -> 2905.5 | Y96: =Y95/2 -> 4371 | Z96: =Z95/2 -> 6583.5066 | AA96: =AA95/2 -> 1557.5 | AB96: =AB95/2 -> 5998.5 | AH96: =AVERAGE(V96:AG96) -> 4891.8581
W99: NOTAS FISCAIS DE DEVOLUÇÃO DE GARANTIA
A120: Mês | D120: jan | E120: fev | F120: mar | G120: abr | H120: mai | I120: jun | J120: jul | K120: ago | L120: set | M120: out | N120: nov | O120: dez | P120: Média | Q120: Res.%
A121: Tx Reclamação | D121: =(13/142) -> 0.091549296 | E121: =28/142 -> 0.1971831 | F121: =14/142 -> 0.098591549 | G121: =21/142 -> 0.14788732 | H121: 0.035211268 | I121: =4/142 -> 0.028169014 | J121: =5/142 -> 0.035211268
A122: Reclam/ procedencia | D122: =(2/13) -> 0.15384615 | E122: =28/28 -> 1 | F122: 1 | G122: 1 | H122: 1 | I122: 1 | J122: 1
E126: NOTAS FISCAIS DE DEVOLUÇÃO DE GARANTIA

Sheet MANUTENÇÃO
S21: Mês | U21: jan | V21: fev | W21: mar | X21: abr | Y21: mai | Z21: jun | AA21: jul | AB21: ago | AC21: set | AD21: out | AE21: nov | AF21: dez | AG21: Total R$ | AH21: Resultado | AK21: Mês | AM21: jan | AN21: fev | AO21: mar | AP21: abr | AQ21: mai | AR21: jun | AS21: jul | AT21: ago | AU21: set | AV21: out | AW21: nov | AX21: dez | AY21: Total R$ | AZ21: Resultado
A22: Mês | C22: jan | D22: fev | E22: mar | F22: abr | G22: mai | H22: jun | I22: jul | J22: ago | K22: set | L22: out | M22: nov | N22: dez | O22: Total R$ | P22: Res.% | S22: Meta | T22: 0.025 | U22: 0.025 | V22: 0.025 | W22: 0.025 | X22: 0.025 | Y22: 0.025 | Z22: 0.025 | AA22: 0.025 | AB22: 0.025 | AC22: 0.025 | AD22: 0.025 | AE22: 0.025 | AF22: 0.025 | AK22: Meta | AL22: 3 | AM22: 3 | AN22: 3 | AO22: 3 | AP22: 3 | AQ22: 3 | AR22: 3 | AS22: 3 | AT22: 3 | AU22: 3 | AV22: 3 | AW22: 3 | AX22: 3 | AZ22: =AY23/AL22 -> 0.095349381
A23: Meta | B23: =[2]Resultados!$C$60 -> 250475 | C23: 250475 | D23: 250475 | E23: 250475 | F23: 250475 | G23: 250475 | H23: 250475 | I23: 250475 | J23: 250475 | K23: 250475 | L23: 250475 | M23: 250475 | N23: 250475 | S23: Resultado | U23: =U24/U25 -> 0.031831878 | V23: =V24/V25 -> 0.0013491411 | W23: =W24/W25 -> 0.024695374 | X23: =X24/X25 -> 0.069582305 | Y23: =Y24/Y25 -> 0.029372972 | Z23: =Z24/Z25 -> 0.018465709 | AA23: =AA24/AA25 -> 0 | AG23: =SUM(U23:AF23) -> 0.17529738 | AH23: =AG23/T22 -> 7.0118952 | AK23: Resultado | AM23: =AM24/AM25 -> 0.41711607 | AN23: =AN24/AN25 -> 0.031490937 | AO23: =AO24/AO25 -> 0.33020531 | AP23: =AP24/AP25 -> 0.61220532 | AQ23: =AQ24/AQ25 -> 0.37165019 | AR23: =AR24/AR25 -> 0.23966918 | AS23: 0 | AY23: =AVERAGE(AM23:AX23) -> 0.28604814
A24: Previsão Redução R$ | C24: 0 | D24: 0 | E24: 0 | F24: 0 | G24: 0 | H24: 0 | I24: 0 | O24: =SUM(C24:N24) -> 0 | P24: =O25/B23 -> 0.08990518 | S24: Manutenção R$ | U24: 30406.51 | V24: 1938.96 | W24: 21310.46 | X24: 42412.36 | Y24: 21206.36 | Z24: 9693.42 | AA24: 0 | AK24: Valor Manutenção R$ | AM24: =U24 -> 30406.51 | AN24: =V24 -> 1938.96 | AO24: =W24 -> 21310.46 | AP24: =X24 -> 42412.36 | AQ24: =Y24 -> 21206.36 | AR24: =Z24 -> 9693.42 | AS24: 0
A25: Redução R$ | C25: 12169 | D25: 7000 | E25: 0 | F25: 0 | G25: 3350 | H25: 0 | I25: 0 | O25: =SUM(C25:N25) -> 22519 | S25: Faturamento R$ | U25: 955222 | V25: 1437181 | W25: 862933.26 | X25: =COMERCIAL!F29 -> 609527.95 | Y25: =COMERCIAL!G29 -> 721968.48 | Z25: =COMERCIAL!H29 -> 524941.65 | AA25: =COMERCIAL!I29 -> 660030.43 | AK25: Volume Produzido | AM25: 72897 | AN25: 61572 | AO25: 64537 | AP25: 69278 | AQ25: 57060 | AR25: 40445 | AS25: 0
A26: Redução Acumulada R$ | C26: =C25 -> 12169 | D26: =C26+D25 -> 19169 | E26: =D26+E25 -> 19169 | F26: =E26+F25 -> 19169 | G26: =F26+G25 -> 22519 | H26: =G26+H25 -> 22519 | I26: =H26+I25 -> 22519 | J26: =I26+J25 -> 22519 | K26: =J26+K25 -> 22519 | ... N26: =M26+N25 -> 22519
A27: Percentual % | C27: =C26/B23 -> 0.048583691 | D27: =D26/C23 -> 0.076530592
A28: Descrição | C28: Sist Hidraul | D28: Lub.Externa 4eixo | G28: Manut Interna do compressor

Sheet PROCESSOS
A22: Mês | C22: jan | D22: fev | E22: mar | F22: abr | G22: mai | H22: jun | I22: jul | J22: ago | K22: set | L22: out | M22: nov | N22: dez | O22: Total R$ | P22: Res.%
A23: Meta | B23: =[2]Resultados!$C$100 -> 402391 | C23: =[2]Resultados!$C$100 -> 402391 | D23: =[2]Resultados!$C$100 -> 402391 | E23: =[2]Resultados!$C$100 -> 402391 | F23: =[2]Resultados!$C$100 -> 402391 | G23: =[2]Resultados!$C$100 -> 402391 | H23: =[2]Resultados!$C$100 -> 402391 | I23: =[2]Resultados!$C$100 -> 402391 | ... N23: =[2]Resultados!$C$100 -> 402391
A24: Redução R$ | C24: 3354.75 | D24: 3354.75 | E24: 3354.75 | F24: 3354.75 | O24: =SUM(C24:N24) -> 13419 | P24: =(O24/B23)*100 -> 3.3348161
A25: Redução Acumulada R$ | C25: =C24 -> 3354.75 | D25: =C25+D24 -> 6709.5 | E25: =D25+E24 -> 10064.25 | F25: =E25+F24 -> 13419
A26: Percentual % | C26: =(C25/C23)*100 -> 0.83370403 | D26: =(D25/D23)*100 -> 1.6674081 | E26: =(E25/E23)*100 -> 2.5011121 | F26: =(F25/F23)*100 -> 3.3348161
A27: Descrição | C27: EVBST0201/EVBST0033/EVROL0004/0005 | D27: EVBST0201/EVBST0033/EVROL0004/0006 | E27: EVBST0201/EVBST0033/EVROL0004/0007 | F27: EVBST0201/EVBST0033/EVROL0004/0008
A52: Mês | C52: jan | D52: fev | E52: mar | F52: abr | G52: mai | H52: jun | I52: jul | J52: ago | K52: set | L52: out | M52: nov | N52: dez | O52: Média % | P52: Res.%
A53: Meta | B53: 0.38 | C53: 0.38 | D53: 0.38 | E53: 0.38 | F53: 0.38 | G53: 0.38 | H53: 0.38 | I53: 0.38 | J53: 0.38 | K53: 0.38 | L53: 0.38 | M53: 0.38 | N53: 0.38
A54: Resultado % | C54: =[4]Refugo!$E$7 -> 0.29493669 | D54: 0.27 | E54: 0.5 | F54: 0.28 | G54: 0.26 | H54: 0.48 | I54: 0 | O54: =AVERAGE(C54:N54) -> 0.2978481 | P54: =(O54/B53)*100 -> 78.381079
A80: Mês | C80: jan | D80: fev | E80: mar | F80: abr | G80: mai | H80: jun | I80: jul | J80: ago | K80: set | L80: out | M80: nov | N80: dez | O80: Média % | P80: Res.%
A81: Meta | B81: 90 | C81: 90 | D81: 90 | E81: 90 | F81: 90 | G81: 90 | H81: 90 | I81: 90 | J81: 90 | K81: 90 | L81: 90 | M81: 90 | N81: 90
A82: Resultado % | C82: 87.69 | D82: 87.69 | E82: 87.69 | F82: 94.95 | G82: =F82 -> 94.95 | H82: =G82 -> 94.95 | I82: =H82 -> 94.95 | O82: =AVERAGE(C82:N82) -> 91.838571 | P82: =(O82/B81)*100 -> 102.04286
A104: Janeiro | D104: Fevereiro | G104: Março | J104: Abril
A105: EVPCE7628 | B105: 802 | D105: EVPCE7607 | E105: 220 | G105: EVPCE7607 | H105: 540 | J105: EVPCE7613 | K105: 282
A106: HPBJ0003 | B106: 2577 | D106: HPBJ0003 | E106: 5658 | G106: EVPCE7628 | H106: 956 | J106: EVPCE7680 | K106: 560
A107: HPCE0001 | B107: 5114 | D107: HPCE0001 | E107: 7748 | G107: EVPCE7694 | H107: 550 | J107: EVPCE7682 | K107: 910
A108: HPCE0009 | B108: 3684 | D108: HPCE0016 | E108: 1112 | G108: HPBJ0001 | H108: 591 | J108: EVPCE7691 | K108: 394
A109: HPCE0016 | B109: 1644 | D109: HPCE0017 | E109: 856 | G109: HPBJ0002 | H109: 2643 | J109: EVPCE7693 | K109: 318
A110: HPCE0017 | B110: 920 | D110: HPCE0036 | E110: 4496 | G110: HPBJ0003 | H110: 3168 | J110: EVPCM7003 | K110: 702
A111: HPCE0036 | B111: 3108 | D111: HPCE0038 | E111: 2046 | G111: HPBJ0004 | H111: 647 | J111: EVPCR5301 | K111: 104
A112: HPCE0038 | B112: 4412 | D112: HPCE7695 | E112: 1322 | G112: HPCE0001 | H112: 7508 | J112: HPBJ0003 | K112: 6167
A113: HPCE7629 | B113: 878 | D113: HPCE7696 | E113: 398 | G113: HPCE0016 | H113: 630 | J113: HPCE0001 | K113: 8516
A114: HPCE7695 | B114: 2122 | D114: HPCM0003 | E114: 750 | G114: HPCE0017 | H114: 1430 | J114: HPCE0016 | K114: 1172
A115: HPCE7696 | B115: 690 | D115: HPCM0011 | E115: 3918 | G115: HPCE7629 | H115: 686 | J115: HPCE0017 | K115: 3334
A116: HPCM0011 | B116: 6998 | D116: HPCM0015 | E116: 532 | G116: HPCE7695 | H116: 776 | J116: HPCE7682 | K116: 0
... A130: HPCR0094 | B130: 952 | D130: HPCR0095 | E130: 498 | G130: HPCM0146 | H130: 3066 | J130: HPCM7168 | K130: 1287
B131: =SUM(B105:B130) -> 72897 | E131: =SUM(E105:E130) -> 61572 | G131: HPCM7075 | H131: 262 | J131: HPCR0092 | K131: 1582
G132: HPCM7082 | H132: 834 | J132: HPCR0094 | K132: 2468
G133: HPCM7097 | H133: 970 | J133: HPCR0095 | K133: 784
G134: HPCM7168 | H134: 3282 | K134: =SUM(K105:K133) -> 69278
G135: HPCR0092 | H135: 426
G136: HPCR0093 | H136: 1380
G137: HPCR0094 | H137: 1784
G138: HPCR0095 | H138: 1563
H139: =SUM(H105:H138) -> 64537

Sheet COMERCIAL
A23: Mês | C23: jan | D23: fev | E23: mar | F23: abr | G23: mai | H23: jun | I23: jul | J23: ago | K23: set | L23: out | M23: nov | N23: dez | O23: Total | P23: Res.% | R23: Mês | T23: jan | U23: fev | V23: mar | W23: abr | X23: mai | Y23: jun | Z23: jul | AA23: ago | AB23: set | AC23: out | AD23: nov | AE23: dez | AF23: Total | AG23: Res.%
A24: Meta | B24: 19000000 | C24: 19000000 | D24: 19000000 | E24: 19000000 | F24: 19000000 | G24: 19000000 | H24: 19000000 | I24: 19000000 | J24: 19000000 | K24: 19000000 | L24: 19000000 | M24: 19000000 | N24: 19000000
A25: Vendas Varejo | C25: 128094.34 | D25: 104918 | E25: 162270 | F25: 164480.12 | G25: 159330 | H25: 77074.73 | I25: 186693.33 | O25: =SUM(C25:N25) -> 982860.52 | P25: =O29/B24 -> 0.24822561 | R25: Vendas Varejo | T25: 1655 | U25: 1429 | V25: 2409 | W25: 2059 | X25: 1443 | AF25: =SUM(T25:AE25) -> 8995
A26: Vendas ZF Brasil | C26: 569004.45 | D26: 487896 | E26: 700663.26 | F26: 445047.83 | G26: 562638.48 | H26: 447866.92 | I26: 473337.1 | O26: =SUM(C26:N26) -> 3686454 | R26: Vendas ZF Brasil | T26: 6864 | U26: 5756 | V26: 8576 | W26: 8331 | X26: 3466 | Y26: 3632 | Z26: 1446 | AF26: =SUM(T26:AE26) -> 38071
A27: Vendas SFA | C27: 0 | D27: 0 | E27: 0 | F27: 0 | G27: 0 | O27: =SUM(C27:N27) -> 0 | R27: Vendas SFA (Serviço) | T27: 42693 | U27: 53430 | V27: 58181 | W27: 51953 | X27: 57060 | Y27: 33744 | Z27: 2953 | AF27: =SUM(T27:AE27) -> 300014
A28: Vendas Exportação | C28: 0 | D28: 46972 | E28: 0 | F28: 0 | G28: 0 | O28: =SUM(C28:N28) -> 46972 | R28: Vendas Exportação | T28: 0 | U28: 1353 | AF28: =SUM(T28:AE28) -> 1353
A29: Total Faturamento | C29: =SUM(C25:C28) -> 697098.79 | D29: =SUM(D25:D28) -> 639786 | E29: =SUM(E25:E28) -> 862933.26 | F29: =SUM(F25:F28) -> 609527.95 | G29: =SUM(G25:G28) -> 721968.48 | H29: =SUM(H25:H28) -> 524941.65 | I29: =SUM(I25:I28) -> 660030.43 | J29: =SUM(J25:J28) -> 0 | ... O29: =SUM(O25:O28) -> 4716286.6 | R29: Total | T29: =SUM(T25:T28) -> 51212 | U29: =SUM(U25:U28) -> 61968 | V29: =SUM(V25:V28) -> 69166 | W29: =SUM(W25:W28) -> 62343 | X29: =SUM(X25:X28) -> 61969 | Y29: =SUM(Y25:Y28) -> 37376 | Z29: =SUM(Z25:Z28) -> 4399 | AA29: =SUM(AA25:AA28) -> 0 | ... AF29: =SUM(AF25:AF28) -> 348433

Sheet ENGENHARIA
A22: Mês | C22: jan | D22: fev | E22: mar | F22: abr | G22: mai | H22: jun | I22: jul | J22: ago | K22: set | L22: out | M22: nov | N22: dez | O22: Total R$ | P22: Res.%
A23: Meta | B23: =[2]Resultados!$C$124 -> 406115 | C23: 406115 | D23: 406115 | E23: 406115 | F23: 406115 | G23: 406115 | H23: 406115 | I23: 406115 | J23: 406115 | K23: 406115 | L23: 406115 | M23: 406115 | N23: 406115
A24: Previsão Redução Mês R$ | C24: 74932 | D24: 0 | E24: 0
A25: Redução R$ | D25: 0 | E25: 0 | O25: =SUM(C25:N25) -> 0 | P25: =(O25/B23)*100 -> 0
A26: Redução Acumulada R$ | C26: =C25 -> 0 | D26: 0 | E26: 0 | O26: =SUM(C26:N26) -> 0
A27: Percentual % | C27: =(C26/C23)*100 -> 0 | D27: 0 | E27: 0
A28: Descrição | C28: EVCM8159
A52: Mês | C52: jan | D52: fev | E52: mar | F52: abr | G52: mai | H52: jun | I52: jul | J52: ago | K52: set | L52: out | M52: nov | N52: dez | O52: Total | P52: Res.% | S52: Mês | U52: jan | V52: fev | W52: mar | X52: abr | Y52: mai | Z52: jun | AA52: jul | AB52: ago | AC52: set | AD52: out | AE52: nov | AF52: dez | AG52: Total | AH52: Res.%
A53: Meta | B53: 48 | C53: 48 | D53: 48 | E53: 48 | F53: 48 | G53: 48 | H53: 48 | I53: 48 | J53: 48 | K53: 48 | L53: 48 | M53: 48 | N53: 48 | S53: Meta | T53: 48 | U53: 48 | V53: 48 | W53: 48 | X53: 48 | Y53: 48 | Z53: 48 | AA53: 48 | AB53: 48 | AC53: 48 | AD53: 48 | AE53: 48 | AF53: 48
A54: Projetos Implantados | C54: 6 | D54: 0 | E54: 0 | F54: 0 | G54: 0 | H54: 4 | I54: 11 | O54: =SUM(C54:N54) -> 21 | P54: =(O54/B53)*100 -> 43.75 | S54: Projetos Implantados | U54: 6 | V54: 0 | W54: 0 | X54: 0 | Y54: 0 | Z54: 4 | AA54: 11 | AG54: =SUM(U54:AF54) -> 21 | AH54: =(AG54/T53)*100 -> 43.75
A55: Redução Prevista R$ | C55: 74932 | D55: 0 | E55: 0 | F55: 0 | G55: 0 | H55: 0 | I55: 0 | O55: =SUM(C55:N55) -> 74932
A56: Redução Acumulada R$
A57: Produtos | B57: Mèdia Mês
A58: EVCM7176
A59: EVCM7200
A60: EVCM7195
A61: EVCM7196
A62: EVCM7186
A63: EVCM7186
A64: EVCM7206
A65: EVCR5300
A66: EVCR5301
A67: EVCR5302
A68: EVCR5303
A69: EVCM7000
... A75: EVCM7173
